async function usingTryCatch() {
 try {
   let resolveValue = await asyncFunction('thing that will fail');
   let secondValue = await secondAsyncFunction(resolveValue);
 } catch (err) {
   // Catches any errors in the try block
   console.log(err);
 }
}

usingTryCatch();


// since async functions return promises we can still use native promiseâ€™s .catch()
async function usingPromiseCatch() {
   let resolveValue = await asyncFunction('thing that will fail');
}

let rejectedPromise = usingPromiseCatch();
rejectedPromise.catch((rejectValue) => {
console.log(rejectValue);
})
